orderbook-core/src/test/resources/backtest/snapshots_full.csv
timestamp_ms,best_bid,best_ask,bid_price_0,bid_qty_0,bid_price_1,bid_qty_1,ask_price_0,ask_qty_0,ask_price_1,ask_qty_1
1700000000000,49990.0,50010.0,49990.0,1.5,49980.0,2.0,50010.0,1.0,50020.0,1.5
1700010000000,50000.0,50020.0,50000.0,2.0,49990.0,1.5,50020.0,1.5,50030.0,2.0
1700020000000,50010.0,50030.0,50010.0,1.0,50000.0,2.5,50030.0,2.0,50040.0,1.0
